Workbook

Sheet State Data 2-13-202
A1: Column1 | B1: State | C1: _1 | D1: Relationship andParental Recognition | E1: Non–Discrimination | F1: Religious Exemption Laws | G1: LGBT Youth | H1: Healthcare | I1: CriminalJustice | J1: IdentityDocuments | K1: Sexual Orientation Policy Tally | L1: Gender Identity Policy Tally | M1: Overall Tally
A2: 1 | B2: Alabama | C2: SO | D2: 1/7 | E2: 0/4.5 | F2: -2/-3.5 | G2: -1/5 | H2: 0/3.5 | I2: 0/3 | J2: -- | K2: -2 | L2: -8.5 | M2: -10.5
C3: GI | D3: 0/1 | E3: -1.5/4.5 | F3: -2/-2.5 | G3: -3.5/5 | H3: -1/8.5 | I3: 0/3 | J3: -0.5/4
A4: 2 | B4: Alaska | C4: SO | D4: 1/7 | E4: 1.75/4.5 | F4: 0/-3.5 | G4: 0.25/5 | H4: 0.5/3.5 | I4: 0.75/3 | J4: -- | K4: 4.25 | L4: 4 | M4: 8.25
C5: GI | D5: 0/1 | E5: 1.75/4.5 | F5: 0/-2.5 | G5: -0.5/5 | H5: 1.5/8.5 | I5: -0.25/3 | J5: 1.5/4
A6: 3 | B6: American Samoa | C6: SO | D6: 1/7 | E6: 0/4.5 | F6: 0/-3.5 | G6: 0/5 | H6: 0/3.5 | I6: 0/3 | J6: -- | K6: 1 | L6: -1 | M6: 0
C7: GI | D7: 0/1 | E7: 0/4.5 | F7: 0/-2.5 | G7: 0/5 | H7: 0/8.5 | I7: 0/3 | J7: -1/4
A8: 4 | B8: Arizona | C8: SO | D8: 2/7 | E8: 2.75/4.5 | F8: -1.5/-3.5 | G8: 0.75/5 | H8: 0.5/3.5 | I8: 2/3 | J8: -- | K8: 6.5 | L8: 2.25 | M8: 8.75
C9: GI | D9: 1/1 | E9: 2.75/4.5 | F9: -1.5/-2.5 | G9: -0.25/5 | H9: -0.75/8.5 | I9: 0/3 | J9: 1/4
A10: 5 | B10: Arkansas | C10: SO | D10: 1/7 | E10: -1/4.5 | F10: -3.5/-3.5 | G10: -0.5/5 | H10: 1/3.5 | I10: -1/3 | J10: -- | K10: -4 | L10: -10.25 | M10: -14.25
C11: GI | D11: 0/1 | E11: -2/4.5 | F11: -2.5/-2.5 | G11: -2.75/5 | H11: -1.5/8.5 | I11: -1/3 | J11: -0.5/4
A12: 6 | B12: California | C12: SO | D12: 7/7 | E12: 4.5/4.5 | F12: 0/-3.5 | G12: 5/5 | H12: 2.5/3.5 | I12: 2.75/3 | J12: -- | K12: 21.75 | L12: 23.25 | M12: 45
C13: GI | D13: 1/1 | E13: 4.5/4.5 | F13: 0/-2.5 | G13: 5/5 | H13: 6/8.5 | I13: 2.75/3 | J13: 4/4
A14: 7 | B14: Colorado | C14: SO | D14: 7/7 | E14: 4.5/4.5 | F14: 0/-3.5 | G14: 5/5 | H14: 3/3.5 | I14: 2.75/3 | J14: -- | K14: 22.25 | L14: 23 | M14: 45.25
C15: GI | D15: 1/1 | E15: 4.5/4.5 | F15: 0/-2.5 | G15: 5/5 | H15: 6/8.5 | I15: 2.75/3 | J15: 3.75/4
A16: 8 | B16: Connecticut | C16: SO | D16: 6/7 | E16: 4.5/4.5 | F16: -0.5/-3.5 | G16: 4.5/5 | H16: 2.25/3.5 | I16: 2/3 | J16: -- | K16: 18.75 | L16: 22 | M16: 40.75
C17: GI | D17: 1/1 | E17: 4.5/4.5 | F17: -0.5/-2.5 | G17: 4.5/5 | H17: 6.75/8.5 | I17: 2/3 | J17: 3.75/4
A18: 9 | B18: Delaware | C18: SO | D18: 3.75/7 | E18: 3.5/4.5 | F18: 0/-3.5 | G18: 2.5/5 | H18: 2.75/3.5 | I18: 1.5/3 | J18: -- | K18: 14 | L18: 17 | M18: 31
C19: GI | D19: 1/1 | E19: 3.5/4.5 | F19: 0/-2.5 | G19: 2/5 | H19: 6.5/8.5 | I19: 1.5/3 | J19: 2.5/4
A20: 10 | B20: District of Columbia | C20: SO | D20: 5/7 | E20: 4.5/4.5 | F20: 0/-3.5 | G20: 4/5 | H20: 3/3.5 | I20: 2/3 | J20: -- | K20: 18.5 | L20: 22.25 | M20: 40.75
C21: GI | D21: 1/1 | E21: 4.5/4.5 | F21: 0/-2.5 | G21: 4/5 | H21: 7/8.5 | I21: 2/3 | J21: 3.75/4
A22: 11 | B22: Florida | C22: SO | D22: 1/7 | E22: 2.75/4.5 | F22: -1.5/-3.5 | G22: -0.5/5 | H22: 0.5/3.5 | I22: 0.5/3 | J22: -- | K22: 2.75 | L22: -5.75 | M22: -3
C23: GI | D23: 0/1 | E23: 1.75/4.5 | F23: -1.5/-2.5 | G23: -2.5/5 | H23: -2/8.5 | I23: -0.5/3 | J23: -1/4
A24: 12 | B24: Georgia | C24: SO | D24: 1/7 | E24: 0/4.5 | F24: -0.5/-3.5 | G24: 0/5 | H24: 0.5/3.5 | I24: 0.5/3 | J24: -- | K24: 1.5 | L24: -2.25 | M24: -0.75
C25: GI | D25: 0/1 | E25: 0/4.5 | F25: -0.5/-2.5 | G25: -1/5 | H25: 1.25/8.5 | I25: 0.5/3 | J25: -2.5/4
A26: 13 | B26: Guam | C26: SO | D26: 1.75/7 | E26: 1.5/4.5 | F26: 0/-3.5 | G26: 1/5 | H26: 0.5/3.5 | I26: 0.75/3 | J26: -- | K26: 5.5 | L26: -0.75 | M26: 4.75
C27: GI | D27: 0/1 | E27: 1.5/4.5 | F27: 0/-2.5 | G27: 0/5 | H27: 0.5/8.5 | I27: -0.25/3 | J27: -2.5/4
A28: 14 | B28: Hawaii | C28: SO | D28: 4.5/7 | E28: 3.5/4.5 | F28: 0/-3.5 | G28: 3.5/5 | H28: 1.5/3.5 | I28: 3/3 | J28: -- | K28: 16 | L28: 17.25 | M28: 33.25
C29: GI | D29: 1/1 | E29: 3.5/4.5 | F29: 0/-2.5 | G29: 3.5/5 | H29: 4/8.5 | I29: 3/3 | J29: 2.25/4
A30: 15 | B30: Idaho | C30: SO | D30: 2/7 | E30: 0.75/4.5 | F30: -2.5/-3.5 | G30: -1/5 | H30: 0/3.5 | I30: 0.5/3 | J30: -- | K30: -0.25 | L30: -11.25 | M30: -11.5
C31: GI | D31: 0/1 | E31: -0.75/4.5 | F31: -2.5/-2.5 | G31: -3.25/5 | H31: -2.5/8.5 | I31: -0.5/3 | J31: -1.75/4
A32: 16 | B32: Illinois | C32: SO | D32: 7/7 | E32: 4.5/4.5 | F32: -1.5/-3.5 | G32: 5/5 | H32: 3.5/3.5 | I32: 3/3 | J32: -- | K32: 21.5 | L32: 23.5 | M32: 45
C33: GI | D33: 1/1 | E33: 4.5/4.5 | F33: -1.5/-2.5 | G33: 5/5 | H33: 7.5/8.5 | I33: 3/3 | J33: 4/4
A34: 17 | B34: Indiana | C34: SO | D34: 3/7 | E34: 1.25/4.5 | F34: -0.5/-3.5 | G34: -1/5 | H34: 1/3.5 | I34: -1/3 | J34: -- | K34: 2.75 | L34: -5.5 | M34: -2.75
C35: GI | D35: 0/1 | E35: 0.5/4.5 | F35: -0.5/-2.5 | G35: -3/5 | H35: 0/8.5 | I35: -1/3 | J35: -1.5/4
A36: 18 | B36: Iowa | C36: SO | D36: 2/7 | E36: 4.5/4.5 | F36: -0.5/-3.5 | G36: 2/5 | H36: 1/3.5 | I36: 0.5/3 | J36: -- | K36: 9.5 | L36: -5 | M36: 4.5
C37: GI | D37: 1/1 | E37: -0.25/4.5 | F37: -0.5/-2.5 | G37: -2/5 | H37: -1/8.5 | I37: -0.5/3 | J37: -1.75/4
A38: 19 | B38: Kansas | C38: SO | D38: 1/7 | E38: 2.75/4.5 | F38: -1.5/-3.5 | G38: 0/5 | H38: 1/3.5 | I38: 1/3 | J38: -- | K38: 4.25 | L38: -1.75 | M38: 2.5
C39: GI | D39: 0/1 | E39: 1.75/4.5 | F39: -1.5/-2.5 | G39: -1/5 | H39: -0.5/8.5 | I39: 0/3 | J39: -0.5/4
A40: 20 | B40: Kentucky | C40: SO | D40: 2/7 | E40: 2.25/4.5 | F40: -0.5/-3.5 | G40: 0.25/5 | H40: 0.5/3.5 | I40: 0.5/3 | J40: -- | K40: 5 | L40: -0.25 | M40: 4.75
...

Sheet Score System
A1: Column1 | B1: Column2 | C1: Column3 | D1: Column4
A2: Category | B2: Sexual Orientation Tally | C2: Gender Identity Tally | D2: OVERALL Tally
A3: High(75-100% of points possible) | B3: 17.25+ | C3: 19.5+ | D3: 36.75+
A4: Medium(50-74.9% OF POINTS POSSIBLE) | B4: 11.5 to 17 | C4: 13 to 19.25 | D4: 24.5 to 36.5
A5: Fair(25-49.9% of points possible) | B5: 5.75 to 11.25 | C5: 6 to 12.75 | D5: 12.25 to 24.25
A6: Low(0-24.9% of points possible) | B6: 0 to 5.5 | C6: 0 to 5.75 | D6: 0 to 12
A7: Negative(<0 points) | B7: <0 | C7: <0 | D7: <0
A8: Total points possible | B8: 23 | C8: 26 | D8: 49
B13: =C2 -> Gender Identity Tally | D13: =D2 -> OVERALL Tally
B14: smallest | C14: largest | D14: smallest | E14: largest
A15: high | B15: 17.26 | C15: 99 | D15: 36.76 | E15: 99
A16: medium | B16: 11.6 | C16: 17 | D16: 24.6 | E16: 36.5
A17: fair | B17: 5.76 | C17: 11.25 | D17: 12.26 | E17: 24.25
A18: low | B18: 0 | C18: 5.5 | D18: 0 | E18: 12
A19: negative | B19: -99 | C19: -0.01 | D19: -99 | E19: -0.01

Sheet Area Abbreviations
A1: AL | B1: Alabama
A2: AK | B2: Alaska
A3: AZ | B3: Arizona
A4: AR | B4: Arkansas
A5: AS | B5: American Samoa
A6: CA | B6: California
A7: CO | B7: Colorado
A8: CT | B8: Connecticut
A9: DE | B9: Delaware
A10: DC | B10: District of Columbia
A11: FL | B11: Florida
A12: GA | B12: Georgia
... A58: WY | B58: Wyoming

Sheet Formatted Overall mix GI
A2: State | B2: Score | C2: Type
A3: ='State Data 2-13-202'!B2 -> Alabama | B3: -10.5 | C3: Overall
A4: =A3 -> Alabama | B4: -8.5 | C4: GI
A5: ='State Data 2-13-202'!B4 -> Alaska | B5: 8.25 | C5: Overall
A6: =A5 -> Alaska | B6: 4 | C6: GI
A7: ='State Data 2-13-202'!B6 -> American Samoa | B7: 0 | C7: Overall
A8: =A7 -> American Samoa | B8: -1 | C8: GI
A9: ='State Data 2-13-202'!B8 -> Arizona | B9: 8.75 | C9: Overall
A10: =A9 -> Arizona | B10: 2.25 | C10: GI
A11: ='State Data 2-13-202'!B10 -> Arkansas | B11: -14.25 | C11: Overall
A12: =A11 -> Arkansas | B12: -10.25 | C12: GI
A13: ='State Data 2-13-202'!B12 -> California | B13: 45 | C13: Overall
A14: =A13 -> California | B14: 23.25 | C14: GI
A15: ='State Data 2-13-202'!B14 -> Colorado | B15: 45.25 | C15: Overall
A16: =A15 -> Colorado | B16: 23 | C16: GI
A17: ='State Data 2-13-202'!B16 -> Connecticut | B17: 40.75 | C17: Overall
A18: =A17 -> Connecticut | B18: 22 | C18: GI
A19: ='State Data 2-13-202'!B18 -> Delaware | B19: 31 | C19: Overall
A20: =A19 -> Delaware | B20: 17 | C20: GI
A21: ='State Data 2-13-202'!B20 -> District of Columbia | B21: 40.75 | C21: Overall
A22: =A21 -> District of Columbia | B22: 22.25 | C22: GI
A23: ='State Data 2-13-202'!B22 -> Florida | B23: -3 | C23: Overall
A24: =A23 -> Florida | B24: -5.75 | C24: GI
A25: ='State Data 2-13-202'!B24 -> Georgia | B25: -0.75 | C25: Overall
A26: =A25 -> Georgia | B26: -2.25 | C26: GI
A27: ='State Data 2-13-202'!B26 -> Guam | B27: 4.75 | C27: Overall
A28: =A27 -> Guam | B28: -0.75 | C28: GI
A29: ='State Data 2-13-202'!B28 -> Hawaii | B29: 33.25 | C29: Overall
A30: =A29 -> Hawaii | B30: 17.25 | C30: GI
A31: ='State Data 2-13-202'!B30 -> Idaho | B31: -11.5 | C31: Overall
A32: =A31 -> Idaho | B32: -11.25 | C32: GI
A33: ='State Data 2-13-202'!B32 -> Illinois | B33: 45 | C33: Overall
A34: =A33 -> Illinois | B34: 23.5 | C34: GI
A35: ='State Data 2-13-202'!B34 -> Indiana | B35: -2.75 | C35: Overall
A36: =A35 -> Indiana | B36: -5.5 | C36: GI
A37: ='State Data 2-13-202'!B36 -> Iowa | B37: 4.5 | C37: Overall
A38: =A37 -> Iowa | B38: -5 | C38: GI
A39: ='State Data 2-13-202'!B38 -> Kansas | B39: 2.5 | C39: Overall
A40: =A39 -> Kansas | B40: -1.75 | C40: GI
A41: ='State Data 2-13-202'!B40 -> Kentucky | B41: 4.75 | C41: Overall
...

Sheet Gender Identity Scores
A1: ='Formatted Overall mix GI'!$A$4 -> Alabama | B1: ='Formatted Overall mix GI'!$B$4 -> -8.5 | C1: =_xlfn.XLOOKUP(A1,'Area Abbreviations'!B:B,'Area Abbreviations'!A:A) -> AL | D1: =_xlfn.XLOOKUP(B1,'Score System'!$B$15:$B$19,'Score System'!$A$15:$A$19,,-1) -> negative | H1: EXPORT | I1: REM: "" -> ", Starting ", Ending ", Ending , | P1: 462 lines
A2: ='Formatted Overall mix GI'!$A$6 -> Alaska | B2: ='Formatted Overall mix GI'!$B$6 -> 4 | C2: =_xlfn.XLOOKUP(A2,'Area Abbreviations'!B:B,'Area Abbreviations'!A:A) -> AK | D2: =_xlfn.XLOOKUP(B2,'Score System'!$B$15:$B$19,'Score System'!$A$15:$A$19,,-1) -> low | H2: {=_xlfn.TEXTJOIN(CHAR(10), TRUE, "GenderIdentityTally: {", _xlfn.TEXTJOIN(CHAR(10), TRUE, _xlfn.MAP(C1:C59, B1:B59, D1:D59, _xlfn.LAMBDA(_xlpm.abbr,_xlpm.score,_xlpm.grade, IF(_xlpm.abbr <> "", CHAR(9) & """" & _xlpm.abbr & """: {" & CHAR(10) & CHAR(9) & CHAR(9) & """colorGrade"": """ & _xlpm.grade & """," & CHAR(10) & CHAR(9) & CHAR(9) & """score"": " & _xlpm.score & CHAR(10) & CHAR(9) & "},", "") ) ) ), _xlfn.TEXTJOIN(CHAR(10), TRUE, _xlfn.MAP(A1:A59, B1:B59, C1:C59, D1:D59, _xlfn.LAMBDA(_xlpm.state,_xlpm.score,_xlpm.abbr,_xlpm.grade, IF(_xlpm.state <> "", CHAR(9) & """" & _xlpm.state & """: {" & CHAR(10) & CHAR(9) & CHAR(9) & """colorGrade"": """ & _xlpm.grade & """," & CHAR(10) & CHAR(9) & CHAR(9) & """score"": " & _xlpm.score & CHAR(10) & CHAR(9) & "},", "") ) ) ), "}" )} -> GenderIdentityTally: { "AL": { "colorGrade": "negative", "score": -8.5 }, "AK": { "colorGrade": "low", "score": 4 }, "AS": { "colorGrade": "negative", "score": -1 }, "AZ": { "colorGrade": "low", "score": 2.25 }, "AR": { "colorGrade": "negative", "score": -10.25 }, "CA": { "colorGrade": "high", "score": 23.25 }, "CO": { "colorGrade": "high", "score": 23 }, "CT": { "colorGrade": "high", "score": 22 }, "DE": { "colorGrade": "medium", "score": 17 }, "DC": { "colorGrade": "high", "score": 22.25 }, "D.C.": { "colorGrade": "high", "score": 22.25 }, "FL": { "colorGrade": "negative", "score": -5.75 }, "GA": { "colorGrade": "negative", "score": -2.25 }, "GU": { "colorGrade": "negative", "score": -0.75 }, "HI": { "colorGrade": "medium", "score": 17.25 }, "ID": { "colorGrade": "negative", "score": -11.25 }, "IL": { "colorGrade": "high", "score": 23.5 }, "IN": { "colorGrade": "negative", "score": -5.5 }, "IA": { "colorGrade": "negative", "score": -5 }, "KS": { "colorGrade": "negative", "score": -1.75 }, "KY": { "colorGrade": "negative", "score": -0.25 }, "LA": { "colorGrade": "negative", "score": -7.25 }, "ME": { "colorGrade": "high", "score": 23.5 }, "MD": { "colorGrade": "high", "score": 23 }, "MA": { "colorGrade": "high", "score": 21.75 }, "MI": { "colorGrade": "medium", "score": 16.5 }, "MN": { "colorGrade": "high", "score": 20.75 }, "MS": { "colorGrade": "negative", "score": -6.5 }, "MO": { "colorGrade": "negative", "score": -5.5 }, "MT": { "colorGrade": "negative", "score": -6.25 }, "NE": { "colorGrade": "negative", "score": -3 }, "NV": { "colorGrade": "high", "score": 20.75 }, "NH": { "colorGrade": "medium", "score": 15.75 }, "NJ": { "colorGrade": "high", "score": 23.25 }, "NM": { "colorGrade": "high", "score": 20 }, "NY": { "colorGrade": "high", "score": 24 }, "NC": { "colorGrade": "low", "score": 1.5 }, "ND": { "colorGrade": "low", "score": 2 }, "MP": { "colorGrade": "negative", "score": -1.25 }, "OH": { "colorGrade": "negative", "score": -3 }, "OK": { "colorGrade": "negative", "score": -7 }, "OR": { "colorGrade": "high", "score": 21 }, "PA": { "colorGrade": "fair", "score": 10.25 }, "PR": { "colorGrade": "fair", "score": 9.75 }, "RI": { "colorGrade": "high", "score": 20.25 }, "SC": { "colorGrade": "negative", "score": -9.25 }, "SD": { "colorGrade": "negative", "score": -7 }, "TN": { "colorGrade": "negative", "score": -11.25 }, "TX": { "colorGrade": "negative", "score": -8 }, "VI": { "colorGrade": "fair", "score": 6.25 }, "UT": { "colorGrade": "low", "score": 2.25 }, "VT": { "colorGrade": "high", "score": 20.5 }, "VA": { "colorGrade": "medium", "score": 12.25 }, "WA": { "colorGrade": "high", "score": 22 }, "WV": { "colorGrade": "negative", "score": -3.75 }, "WI": { "colorGrade": "low", "score": 5.75 }, "WY": { "colorGrade": "negative", "score": -7.5 }, "Alabama": { "colorGrade": "negative", "score": -8.5 }, "Alaska": { "colorGrade": "low", "score": 4 }, "American Samoa": { "colorGrade": "negative", "score": -1 }, "Arizona": { "colorGrade": "low", "score": 2.25 }, "Arkansas": { "colorGrade": "negative", "score": -10.25 }, "California": { "colorGrade": "high", "score": 23.25 }, "Colorado": { "colorGrade": "high", "score": 23 }, "Connecticut": { "colorGrade": "high", "score": 22 }, "Delaware": { "colorGrade": "medium", "score": 17 }, "District of Columbia": { "colorGrade": "high", "score": 22.25 }, "Florida": { "colorGrade": "negative", "score": -5.75 }, "Georgia": { "colorGrade": "negative", "score": -2.25 }, "Guam": { "colorGrade": "negative", "score": -0.75 }, "Hawaii": { "colorGrade": "medium", "score": 17.25 }, "Idaho": { "colorGrade": "negative", "score": -11.25 }, "Illinois": { "colorGrade": "high", "score": 23.5 }, "Indiana": { "colorGrade": "negative", "score": -5.5 }, "Iowa": { "colorGrade": "negative", "score": -5 }, "Kansas": { "colorGrade": "negative", "score": -1.75 }, "Kentucky": { "colorGrade": "negative", "score": -0.25 }, "Louisiana": { "colorGrade": "negative", "score": -7.25 }, "Maine": { "colorGrade": "high", "score": 23.5 }, "Maryland": { "colorGrade": "high", "score": 23 }, "Massachusetts": { "colorGrade": "high", "score": 21.75 }, "Michigan": { "colorGrade": "medium", "score": 16.5 }, "Minnesota": { "colorGrade": "high", "score": 20.75 }, "Mississippi": { "colorGrade": "negative", "score": -6.5 }, "Missouri": { "colorGrade": "negative", "score": -5.5 }, "Montana": { "colorGrade": "negative", "score": -6.25 }, "Nebraska": { "colorGrade": "negative", "score": -3 }, "Nevada": { "colorGrade": "high", "score": 20.75 }, "New Hampshire": { "colorGrade": "medium", "score": 15.75 }, "New Jersey": { "colorGrade": "high", "score": 23.25 }, "New Mexico": { "colorGrade": "high", "score": 20 }, "New York": { "colorGrade": "high", "score": 24 }, "North Carolina": { "colorGrade": "low", "score": 1.5 }, "North Dakota": { "colorGrade": "low", "score": 2 }, "Northern Mariana Islands": { "colorGrade": "negative", "score": -1.25 }, "Ohio": { "colorGrade": "negative", "score": -3 }, "Oklahoma": { "colorGrade": "negative", "score": -7 }, "Oregon": { "colorGrade": "high", "score": 21 }, "Pennsylvania": { "colorGrade": "fair", "score": 10.25 }, "Puerto Rico": { "colorGrade": "fair", "score": 9.75 }, "Rhode Island": { "colorGrade": "high", "score": 20.25 }, "South Carolina": { "colorGrade": "negative", "score": -9.25 }, "South Dakota": { "colorGrade": "negative", "score": -7 }, "Tennessee": { "colorGrade": "negative", "score": -11.25 }, "Texas": { "colorGrade": "negative", "score": -8 }, "U.S. Virgin Islands": { "colorGrade": "fair", "score": 6.25 }, "US Virgin Islands": { "colorGrade": "fair", "score": 6.25 }, "Virgin Islands": { "colorGrade": "fair", "score": 6.25 }, "Utah": { "colorGrade": "low", "score": 2.25 }, "Vermont": { "colorGrade": "high", "score": 20.5 }, "Virginia": { "colorGrade": "medium", "score": 12.25 }, "Washington": { "colorGrade": "high", "score": 22 }, "West Virginia": { "colorGrade": "negative", "score": -3.75 }, "Wisconsin": { "colorGrade": "low", "score": 5.75 }, "Wyoming": { "colorGrade": "negative", "score": -7.5 }, }
A3: ='Formatted Overall mix GI'!$A$8 -> American Samoa | B3: ='Formatted Overall mix GI'!$B$8 -> -1 | C3: =_xlfn.XLOOKUP(A3,'Area Abbreviations'!B:B,'Area Abbreviations'!A:A) -> AS | D3: =_xlfn.XLOOKUP(B3,'Score System'!$B$15:$B$19,'Score System'!$A$15:$A$19,,-1) -> negative
A4: ='Formatted Overall mix GI'!$A$10 -> Arizona | B4: ='Formatted Overall mix GI'!$B$10 -> 2.25 | C4: =_xlfn.XLOOKUP(A4,'Area Abbreviations'!B:B,'Area Abbreviations'!A:A) -> AZ | D4: =_xlfn.XLOOKUP(B4,'Score System'!$B$15:$B$19,'Score System'!$A$15:$A$19,,-1) -> low
A5: ='Formatted Overall mix GI'!$A$12 -> Arkansas | B5: ='Formatted Overall mix GI'!$B$12 -> -10.25 | C5: =_xlfn.XLOOKUP(A5,'Area Abbreviations'!B:B,'Area Abbreviations'!A:A) -> AR | D5: =_xlfn.XLOOKUP(B5,'Score System'!$B$15:$B$19,'Score System'!$A$15:$A$19,,-1) -> negative
A6: ='Formatted Overall mix GI'!$A$14 -> California | B6: ='Formatted Overall mix GI'!$B$14 -> 23.25 | C6: =_xlfn.XLOOKUP(A6,'Area Abbreviations'!B:B,'Area Abbreviations'!A:A) -> CA | D6: =_xlfn.XLOOKUP(B6,'Score System'!$B$15:$B$19,'Score System'!$A$15:$A$19,,-1) -> high
A7: ='Formatted Overall mix GI'!$A$16 -> Colorado | B7: ='Formatted Overall mix GI'!$B$16 -> 23 | C7: =_xlfn.XLOOKUP(A7,'Area Abbreviations'!B:B,'Area Abbreviations'!A:A) -> CO | D7: =_xlfn.XLOOKUP(B7,'Score System'!$B$15:$B$19,'Score System'!$A$15:$A$19,,-1) -> high
A8: ='Formatted Overall mix GI'!$A$18 -> Connecticut | B8: ='Formatted Overall mix GI'!$B$18 -> 22 | C8: =_xlfn.XLOOKUP(A8,'Area Abbreviations'!B:B,'Area Abbreviations'!A:A) -> CT | D8: =_xlfn.XLOOKUP(B8,'Score System'!$B$15:$B$19,'Score System'!$A$15:$A$19,,-1) -> high
A9: ='Formatted Overall mix GI'!$A$20 -> Delaware | B9: ='Formatted Overall mix GI'!$B$20 -> 17 | C9: =_xlfn.XLOOKUP(A9,'Area Abbreviations'!B:B,'Area Abbreviations'!A:A) -> DE | D9: =_xlfn.XLOOKUP(B9,'Score System'!$B$15:$B$19,'Score System'!$A$15:$A$19,,-1) -> medium
A10: ='Formatted Overall mix GI'!$A$22 -> District of Columbia | B10: ='Formatted Overall mix GI'!$B$22 -> 22.25 | C10: =_xlfn.XLOOKUP(A10,'Area Abbreviations'!B:B,'Area Abbreviations'!A:A) -> DC | D10: =_xlfn.XLOOKUP(B10,'Score System'!$B$15:$B$19,'Score System'!$A$15:$A$19,,-1) -> high
B11: =B10 -> 22.25 | C11: D.C. | D11: =D10 -> high
A12: ='Formatted Overall mix GI'!$A$24 -> Florida | B12: ='Formatted Overall mix GI'!$B$24 -> -5.75 | C12: =_xlfn.XLOOKUP(A12,'Area Abbreviations'!B:B,'Area Abbreviations'!A:A) -> FL | D12: =_xlfn.XLOOKUP(B12,'Score System'!$B$15:$B$19,'Score System'!$A$15:$A$19,,-1) -> negative
A13: ='Formatted Overall mix GI'!$A$26 -> Georgia | B13: ='Formatted Overall mix GI'!$B$26 -> -2.25 | C13: =_xlfn.XLOOKUP(A13,'Area Abbreviations'!B:B,'Area Abbreviations'!A:A) -> GA | D13: =_xlfn.XLOOKUP(B13,'Score System'!$B$15:$B$19,'Score System'!$A$15:$A$19,,-1) -> negative
A14: ='Formatted Overall mix GI'!$A$28 -> Guam | B14: ='Formatted Overall mix GI'!$B$28 -> -0.75 | C14: =_xlfn.XLOOKUP(A14,'Area Abbreviations'!B:B,'Area Abbreviations'!A:A) -> GU | D14: =_xlfn.XLOOKUP(B14,'Score System'!$B$15:$B$19,'Score System'!$A$15:$A$19,,-1) -> negative
A15: ='Formatted Overall mix GI'!$A$30 -> Hawaii | B15: ='Formatted Overall mix GI'!$B$30 -> 17.25 | C15: =_xlfn.XLOOKUP(A15,'Area Abbreviations'!B:B,'Area Abbreviations'!A:A) -> HI | D15: =_xlfn.XLOOKUP(B15,'Score System'!$B$15:$B$19,'Score System'!$A$15:$A$19,,-1) -> medium
A16: ='Formatted Overall mix GI'!$A$32 -> Idaho | B16: ='Formatted Overall mix GI'!$B$32 -> -11.25 | C16: =_xlfn.XLOOKUP(A16,'Area Abbreviations'!B:B,'Area Abbreviations'!A:A) -> ID | D16: =_xlfn.XLOOKUP(B16,'Score System'!$B$15:$B$19,'Score System'!$A$15:$A$19,,-1) -> negative
A17: ='Formatted Overall mix GI'!$A$34 -> Illinois | B17: ='Formatted Overall mix GI'!$B$34 -> 23.5 | C17: =_xlfn.XLOOKUP(A17,'Area Abbreviations'!B:B,'Area Abbreviations'!A:A) -> IL | D17: =_xlfn.XLOOKUP(B17,'Score System'!$B$15:$B$19,'Score System'!$A$15:$A$19,,-1) -> high
A18: ='Formatted Overall mix GI'!$A$36 -> Indiana | B18: ='Formatted Overall mix GI'!$B$36 -> -5.5 | C18: =_xlfn.XLOOKUP(A18,'Area Abbreviations'!B:B,'Area Abbreviations'!A:A) -> IN | D18: =_xlfn.XLOOKUP(B18,'Score System'!$B$15:$B$19,'Score System'!$A$15:$A$19,,-1) -> negative
A19: ='Formatted Overall mix GI'!$A$38 -> Iowa | B19: ='Formatted Overall mix GI'!$B$38 -> -5 | C19: =_xlfn.XLOOKUP(A19,'Area Abbreviations'!B:B,'Area Abbreviations'!A:A) -> IA | D19: =_xlfn.XLOOKUP(B19,'Score System'!$B$15:$B$19,'Score System'!$A$15:$A$19,,-1) -> negative
A20: ='Formatted Overall mix GI'!$A$40 -> Kansas | B20: ='Formatted Overall mix GI'!$B$40 -> -1.75 | C20: =_xlfn.XLOOKUP(A20,'Area Abbreviations'!B:B,'Area Abbreviations'!A:A) -> KS | D20: =_xlfn.XLOOKUP(B20,'Score System'!$B$15:$B$19,'Score System'!$A$15:$A$19,,-1) -> negative
A21: ='Formatted Overall mix GI'!$A$42 -> Kentucky | B21: ='Formatted Overall mix GI'!$B$42 -> -0.25 | C21: =_xlfn.XLOOKUP(A21,'Area Abbreviations'!B:B,'Area Abbreviations'!A:A) -> KY | D21: =_xlfn.XLOOKUP(B21,'Score System'!$B$15:$B$19,'Score System'!$A$15:$A$19,,-1) -> negative
A22: ='Formatted Overall mix GI'!$A$44 -> Louisiana | B22: ='Formatted Overall mix GI'!$B$44 -> -7.25 | C22: =_xlfn.XLOOKUP(A22,'Area Abbreviations'!B:B,'Area Abbreviations'!A:A) -> LA | D22: =_xlfn.XLOOKUP(B22,'Score System'!$B$15:$B$19,'Score System'!$A$15:$A$19,,-1) -> negative
A23: ='Formatted Overall mix GI'!$A$46 -> Maine | B23: ='Formatted Overall mix GI'!$B$46 -> 23.5 | C23: =_xlfn.XLOOKUP(A23,'Area Abbreviations'!B:B,'Area Abbreviations'!A:A) -> ME | D23: =_xlfn.XLOOKUP(B23,'Score System'!$B$15:$B$19,'Score System'!$A$15:$A$19,,-1) -> high
A24: ='Formatted Overall mix GI'!$A$48 -> Maryland | B24: ='Formatted Overall mix GI'!$B$48 -> 23 | C24: =_xlfn.XLOOKUP(A24,'Area Abbreviations'!B:B,'Area Abbreviations'!A:A) -> MD | D24: =_xlfn.XLOOKUP(B24,'Score System'!$B$15:$B$19,'Score System'!$A$15:$A$19,,-1) -> high
A25: ='Formatted Overall mix GI'!$A$50 -> Massachusetts | B25: ='Formatted Overall mix GI'!$B$50 -> 21.75 | C25: =_xlfn.XLOOKUP(A25,'Area Abbreviations'!B:B,'Area Abbreviations'!A:A) -> MA | D25: =_xlfn.XLOOKUP(B25,'Score System'!$B$15:$B$19,'Score System'!$A$15:$A$19,,-1) -> high
A26: ='Formatted Overall mix GI'!$A$52 -> Michigan | B26: ='Formatted Overall mix GI'!$B$52 -> 16.5 | C26: =_xlfn.XLOOKUP(A26,'Area Abbreviations'!B:B,'Area Abbreviations'!A:A) -> MI | D26: =_xlfn.XLOOKUP(B26,'Score System'!$B$15:$B$19,'Score System'!$A$15:$A$19,,-1) -> medium
A27: ='Formatted Overall mix GI'!$A$54 -> Minnesota | B27: ='Formatted Overall mix GI'!$B$54 -> 20.75 | C27: =_xlfn.XLOOKUP(A27,'Area Abbreviations'!B:B,'Area Abbreviations'!A:A) -> MN | D27: =_xlfn.XLOOKUP(B27,'Score System'!$B$15:$B$19,'Score System'!$A$15:$A$19,,-1) -> high
A28: ='Formatted Overall mix GI'!$A$56 -> Mississippi | B28: ='Formatted Overall mix GI'!$B$56 -> -6.5 | C28: =_xlfn.XLOOKUP(A28,'Area Abbreviations'!B:B,'Area Abbreviations'!A:A) -> MS | D28: =_xlfn.XLOOKUP(B28,'Score System'!$B$15:$B$19,'Score System'!$A$15:$A$19,,-1) -> negative
A29: ='Formatted Overall mix GI'!$A$58 -> Missouri | B29: ='Formatted Overall mix GI'!$B$58 -> -5.5 | C29: =_xlfn.XLOOKUP(A29,'Area Abbreviations'!B:B,'Area Abbreviations'!A:A) -> MO | D29: =_xlfn.XLOOKUP(B29,'Score System'!$B$15:$B$19,'Score System'!$A$15:$A$19,,-1) -> negative
A30: ='Formatted Overall mix GI'!$A$60 -> Montana | B30: ='Formatted Overall mix GI'!$B$60 -> -6.25 | C30: =_xlfn.XLOOKUP(A30,'Area Abbreviations'!B:B,'Area Abbreviations'!A:A) -> MT | D30: =_xlfn.XLOOKUP(B30,'Score System'!$B$15:$B$19,'Score System'!$A$15:$A$19,,-1) -> negative
A31: ='Formatted Overall mix GI'!$A$62 -> Nebraska | B31: ='Formatted Overall mix GI'!$B$62 -> -3 | C31: =_xlfn.XLOOKUP(A31,'Area Abbreviations'!B:B,'Area Abbreviations'!A:A) -> NE | D31: =_xlfn.XLOOKUP(B31,'Score System'!$B$15:$B$19,'Score System'!$A$15:$A$19,,-1) -> negative
A32: ='Formatted Overall mix GI'!$A$64 -> Nevada | B32: ='Formatted Overall mix GI'!$B$64 -> 20.75 | C32: =_xlfn.XLOOKUP(A32,'Area Abbreviations'!B:B,'Area Abbreviations'!A:A) -> NV | D32: =_xlfn.XLOOKUP(B32,'Score System'!$B$15:$B$19,'Score System'!$A$15:$A$19,,-1) -> high
A33: ='Formatted Overall mix GI'!$A$66 -> New Hampshire | B33: ='Formatted Overall mix GI'!$B$66 -> 15.75 | C33: =_xlfn.XLOOKUP(A33,'Area Abbreviations'!B:B,'Area Abbreviations'!A:A) -> NH | D33: =_xlfn.XLOOKUP(B33,'Score System'!$B$15:$B$19,'Score System'!$A$15:$A$19,,-1) -> medium
A34: ='Formatted Overall mix GI'!$A$68 -> New Jersey | B34: ='Formatted Overall mix GI'!$B$68 -> 23.25 | C34: =_xlfn.XLOOKUP(A34,'Area Abbreviations'!B:B,'Area Abbreviations'!A:A) -> NJ | D34: =_xlfn.XLOOKUP(B34,'Score System'!$B$15:$B$19,'Score System'!$A$15:$A$19,,-1) -> high
A35: ='Formatted Overall mix GI'!$A$70 -> New Mexico | B35: ='Formatted Overall mix GI'!$B$70 -> 20 | C35: =_xlfn.XLOOKUP(A35,'Area Abbreviations'!B:B,'Area Abbreviations'!A:A) -> NM | D35: =_xlfn.XLOOKUP(B35,'Score System'!$B$15:$B$19,'Score System'!$A$15:$A$19,,-1) -> high
A36: ='Formatted Overall mix GI'!$A$72 -> New York | B36: ='Formatted Overall mix GI'!$B$72 -> 24 | C36: =_xlfn.XLOOKUP(A36,'Area Abbreviations'!B:B,'Area Abbreviations'!A:A) -> NY | D36: =_xlfn.XLOOKUP(B36,'Score System'!$B$15:$B$19,'Score System'!$A$15:$A$19,,-1) -> high
A37: ='Formatted Overall mix GI'!$A$74 -> North Carolina | B37: ='Formatted Overall mix GI'!$B$74 -> 1.5 | C37: =_xlfn.XLOOKUP(A37,'Area Abbreviations'!B:B,'Area Abbreviations'!A:A) -> NC | D37: =_xlfn.XLOOKUP(B37,'Score System'!$B$15:$B$19,'Score System'!$A$15:$A$19,,-1) -> low
A38: ='Formatted Overall mix GI'!$A$76 -> North Dakota | B38: ='Formatted Overall mix GI'!$B$76 -> 2 | C38: =_xlfn.XLOOKUP(A38,'Area Abbreviations'!B:B,'Area Abbreviations'!A:A) -> ND | D38: =_xlfn.XLOOKUP(B38,'Score System'!$B$15:$B$19,'Score System'!$A$15:$A$19,,-1) -> low
A39: ='Formatted Overall mix GI'!$A$78 -> Northern Mariana Islands | B39: ='Formatted Overall mix GI'!$B$78 -> -1.25 | C39: =_xlfn.XLOOKUP(A39,'Area Abbreviations'!B:B,'Area Abbreviations'!A:A) -> MP | D39: =_xlfn.XLOOKUP(B39,'Score System'!$B$15:$B$19,'Score System'!$A$15:$A$19,,-1) -> negative
A40: ='Formatted Overall mix GI'!$A$80 -> Ohio | B40: ='Formatted Overall mix GI'!$B$80 -> -3 | C40: =_xlfn.XLOOKUP(A40,'Area Abbreviations'!B:B,'Area Abbreviations'!A:A) -> OH | D40: =_xlfn.XLOOKUP(B40,'Score System'!$B$15:$B$19,'Score System'!$A$15:$A$19,,-1) -> negative
...

Sheet Overall Tally Scores
A1: ='Formatted Overall mix GI'!$A$3 -> Alabama | B1: ='Formatted Overall mix GI'!$B$3 -> -10.5 | C1: =_xlfn.XLOOKUP(A1,'Area Abbreviations'!B:B,'Area Abbreviations'!A:A) -> AL | D1: =_xlfn.XLOOKUP(B1,'Score System'!$D$15:$D$19,'Score System'!$A$15:$A$19,,-1) -> negative | H1: EXPORT | I1: REM: "" -> ", Starting ", Ending " | P1: 462 lines
A2: ='Formatted Overall mix GI'!$A$5 -> Alaska | B2: ='Formatted Overall mix GI'!$B$5 -> 8.25 | C2: =_xlfn.XLOOKUP(A2,'Area Abbreviations'!B:B,'Area Abbreviations'!A:A) -> AK | D2: =_xlfn.XLOOKUP(B2,'Score System'!$D$15:$D$19,'Score System'!$A$15:$A$19,,-1) -> low | H2: {=_xlfn.TEXTJOIN(CHAR(10), TRUE, "OverallTally: {", _xlfn.TEXTJOIN(CHAR(10), TRUE, _xlfn.MAP(C1:C59, B1:B59, D1:D59, _xlfn.LAMBDA(_xlpm.abbr,_xlpm.score,_xlpm.grade, IF(_xlpm.abbr <> "", CHAR(9) & """" & _xlpm.abbr & """: {" & CHAR(10) & CHAR(9) & CHAR(9) & """colorGrade"": """ & _xlpm.grade & """," & CHAR(10) & CHAR(9) & CHAR(9) & """score"": " & _xlpm.score & CHAR(10) & CHAR(9) & "},", "") ) ) ), _xlfn.TEXTJOIN(CHAR(10), TRUE, _xlfn.MAP(A1:A59, B1:B59, C1:C59, D1:D59, _xlfn.LAMBDA(_xlpm.state,_xlpm.score,_xlpm.abbr,_xlpm.grade, IF(_xlpm.state <> "", CHAR(9) & """" & _xlpm.state & """: {" & CHAR(10) & CHAR(9) & CHAR(9) & """colorGrade"": """ & _xlpm.grade & """," & CHAR(10) & CHAR(9) & CHAR(9) & """score"": " & _xlpm.score & CHAR(10) & CHAR(9) & "},", "") ) ) ), "}" )} -> OverallTally: { "AL": { "colorGrade": "negative", "score": -10.5 }, "AK": { "colorGrade": "low", "score": 8.25 }, "AS": { "colorGrade": "low", "score": 0 }, "AZ": { "colorGrade": "low", "score": 8.75 }, "AR": { "colorGrade": "negative", "score": -14.25 }, "CA": { "colorGrade": "high", "score": 45 }, "CO": { "colorGrade": "high", "score": 45.25 }, "CT": { "colorGrade": "high", "score": 40.75 }, "DE": { "colorGrade": "medium", "score": 31 }, "DC": { "colorGrade": "high", "score": 40.75 }, "D.C.": { "colorGrade": "high", "score": 40.75 }, "FL": { "colorGrade": "negative", "score": -3 }, "GA": { "colorGrade": "negative", "score": -0.75 }, "GU": { "colorGrade": "low", "score": 4.75 }, "HI": { "colorGrade": "medium", "score": 33.25 }, "ID": { "colorGrade": "negative", "score": -11.5 }, "IL": { "colorGrade": "high", "score": 45 }, "IN": { "colorGrade": "negative", "score": -2.75 }, "IA": { "colorGrade": "low", "score": 4.5 }, "KS": { "colorGrade": "low", "score": 2.5 }, "KY": { "colorGrade": "low", "score": 4.75 }, "LA": { "colorGrade": "negative", "score": -6.75 }, "ME": { "colorGrade": "high", "score": 44.5 }, "MD": { "colorGrade": "high", "score": 43 }, "MA": { "colorGrade": "high", "score": 40 }, "MI": { "colorGrade": "medium", "score": 30 }, "MN": { "colorGrade": "medium", "score": 36.75 }, "MS": { "colorGrade": "negative", "score": -7.5 }, "MO": { "colorGrade": "negative", "score": -1.5 }, "MT": { "colorGrade": "negative", "score": -3.75 }, "NE": { "colorGrade": "low", "score": 1.25 }, "NV": { "colorGrade": "high", "score": 42.25 }, "NH": { "colorGrade": "medium", "score": 32 }, "NJ": { "colorGrade": "high", "score": 41.75 }, "NM": { "colorGrade": "medium", "score": 36 }, "NY": { "colorGrade": "high", "score": 44.5 }, "NC": { "colorGrade": "low", "score": 6.25 }, "ND": { "colorGrade": "low", "score": 10.5 }, "MP": { "colorGrade": "low", "score": 2.75 }, "OH": { "colorGrade": "low", "score": 1.75 }, "OK": { "colorGrade": "negative", "score": -5.5 }, "OR": { "colorGrade": "high", "score": 39.5 }, "PA": { "colorGrade": "fair", "score": 16.75 }, "PR": { "colorGrade": "fair", "score": 19.25 }, "RI": { "colorGrade": "high", "score": 38 }, "SC": { "colorGrade": "negative", "score": -9.75 }, "SD": { "colorGrade": "negative", "score": -7.5 }, "TN": { "colorGrade": "negative", "score": -14 }, "TX": { "colorGrade": "negative", "score": -6.75 }, "VI": { "colorGrade": "fair", "score": 15 }, "UT": { "colorGrade": "low", "score": 10 }, "VT": { "colorGrade": "high", "score": 39.5 }, "VA": { "colorGrade": "fair", "score": 24 }, "WA": { "colorGrade": "high", "score": 40.5 }, "WV": { "colorGrade": "negative", "score": -0.75 }, "WI": { "colorGrade": "fair", "score": 18.25 }, "WY": { "colorGrade": "negative", "score": -6 }, "Alabama": { "colorGrade": "negative", "score": -10.5 }, "Alaska": { "colorGrade": "low", "score": 8.25 }, "American Samoa": { "colorGrade": "low", "score": 0 }, "Arizona": { "colorGrade": "low", "score": 8.75 }, "Arkansas": { "colorGrade": "negative", "score": -14.25 }, "California": { "colorGrade": "high", "score": 45 }, "Colorado": { "colorGrade": "high", "score": 45.25 }, "Connecticut": { "colorGrade": "high", "score": 40.75 }, "Delaware": { "colorGrade": "medium", "score": 31 }, "District of Columbia": { "colorGrade": "high", "score": 40.75 }, "Florida": { "colorGrade": "negative", "score": -3 }, "Georgia": { "colorGrade": "negative", "score": -0.75 }, "Guam": { "colorGrade": "low", "score": 4.75 }, "Hawaii": { "colorGrade": "medium", "score": 33.25 }, "Idaho": { "colorGrade": "negative", "score": -11.5 }, "Illinois": { "colorGrade": "high", "score": 45 }, "Indiana": { "colorGrade": "negative", "score": -2.75 }, "Iowa": { "colorGrade": "low", "score": 4.5 }, "Kansas": { "colorGrade": "low", "score": 2.5 }, "Kentucky": { "colorGrade": "low", "score": 4.75 }, "Louisiana": { "colorGrade": "negative", "score": -6.75 }, "Maine": { "colorGrade": "high", "score": 44.5 }, "Maryland": { "colorGrade": "high", "score": 43 }, "Massachusetts": { "colorGrade": "high", "score": 40 }, "Michigan": { "colorGrade": "medium", "score": 30 }, "Minnesota": { "colorGrade": "medium", "score": 36.75 }, "Mississippi": { "colorGrade": "negative", "score": -7.5 }, "Missouri": { "colorGrade": "negative", "score": -1.5 }, "Montana": { "colorGrade": "negative", "score": -3.75 }, "Nebraska": { "colorGrade": "low", "score": 1.25 }, "Nevada": { "colorGrade": "high", "score": 42.25 }, "New Hampshire": { "colorGrade": "medium", "score": 32 }, "New Jersey": { "colorGrade": "high", "score": 41.75 }, "New Mexico": { "colorGrade": "medium", "score": 36 }, "New York": { "colorGrade": "high", "score": 44.5 }, "North Carolina": { "colorGrade": "low", "score": 6.25 }, "North Dakota": { "colorGrade": "low", "score": 10.5 }, "Northern Mariana Islands": { "colorGrade": "low", "score": 2.75 }, "Ohio": { "colorGrade": "low", "score": 1.75 }, "Oklahoma": { "colorGrade": "negative", "score": -5.5 }, "Oregon": { "colorGrade": "high", "score": 39.5 }, "Pennsylvania": { "colorGrade": "fair", "score": 16.75 }, "Puerto Rico": { "colorGrade": "fair", "score": 19.25 }, "Rhode Island": { "colorGrade": "high", "score": 38 }, "South Carolina": { "colorGrade": "negative", "score": -9.75 }, "South Dakota": { "colorGrade": "negative", "score": -7.5 }, "Tennessee": { "colorGrade": "negative", "score": -14 }, "Texas": { "colorGrade": "negative", "score": -6.75 }, "U.S. Virgin Islands": { "colorGrade": "fair", "score": 15 }, "US Virgin Islands": { "colorGrade": "fair", "score": 15 }, "Virgin Islands": { "colorGrade": "fair", "score": 15 }, "Utah": { "colorGrade": "low", "score": 10 }, "Vermont": { "colorGrade": "high", "score": 39.5 }, "Virginia": { "colorGrade": "fair", "score": 24 }, "Washington": { "colorGrade": "high", "score": 40.5 }, "West Virginia": { "colorGrade": "negative", "score": -0.75 }, "Wisconsin": { "colorGrade": "fair", "score": 18.25 }, "Wyoming": { "colorGrade": "negative", "score": -6 }, }
A3: ='Formatted Overall mix GI'!$A$7 -> American Samoa | B3: ='Formatted Overall mix GI'!$B$7 -> 0 | C3: =_xlfn.XLOOKUP(A3,'Area Abbreviations'!B:B,'Area Abbreviations'!A:A) -> AS | D3: =_xlfn.XLOOKUP(B3,'Score System'!$D$15:$D$19,'Score System'!$A$15:$A$19,,-1) -> low
A4: ='Formatted Overall mix GI'!$A$9 -> Arizona | B4: ='Formatted Overall mix GI'!$B$9 -> 8.75 | C4: =_xlfn.XLOOKUP(A4,'Area Abbreviations'!B:B,'Area Abbreviations'!A:A) -> AZ | D4: =_xlfn.XLOOKUP(B4,'Score System'!$D$15:$D$19,'Score System'!$A$15:$A$19,,-1) -> low
A5: ='Formatted Overall mix GI'!$A$11 -> Arkansas | B5: ='Formatted Overall mix GI'!$B$11 -> -14.25 | C5: =_xlfn.XLOOKUP(A5,'Area Abbreviations'!B:B,'Area Abbreviations'!A:A) -> AR | D5: =_xlfn.XLOOKUP(B5,'Score System'!$D$15:$D$19,'Score System'!$A$15:$A$19,,-1) -> negative
A6: ='Formatted Overall mix GI'!$A$13 -> California | B6: ='Formatted Overall mix GI'!$B$13 -> 45 | C6: =_xlfn.XLOOKUP(A6,'Area Abbreviations'!B:B,'Area Abbreviations'!A:A) -> CA | D6: =_xlfn.XLOOKUP(B6,'Score System'!$D$15:$D$19,'Score System'!$A$15:$A$19,,-1) -> high
A7: ='Formatted Overall mix GI'!$A$15 -> Colorado | B7: ='Formatted Overall mix GI'!$B$15 -> 45.25 | C7: =_xlfn.XLOOKUP(A7,'Area Abbreviations'!B:B,'Area Abbreviations'!A:A) -> CO | D7: =_xlfn.XLOOKUP(B7,'Score System'!$D$15:$D$19,'Score System'!$A$15:$A$19,,-1) -> high
A8: ='Formatted Overall mix GI'!$A$17 -> Connecticut | B8: ='Formatted Overall mix GI'!$B$17 -> 40.75 | C8: =_xlfn.XLOOKUP(A8,'Area Abbreviations'!B:B,'Area Abbreviations'!A:A) -> CT | D8: =_xlfn.XLOOKUP(B8,'Score System'!$D$15:$D$19,'Score System'!$A$15:$A$19,,-1) -> high
A9: ='Formatted Overall mix GI'!$A$19 -> Delaware | B9: ='Formatted Overall mix GI'!$B$19 -> 31 | C9: =_xlfn.XLOOKUP(A9,'Area Abbreviations'!B:B,'Area Abbreviations'!A:A) -> DE | D9: =_xlfn.XLOOKUP(B9,'Score System'!$D$15:$D$19,'Score System'!$A$15:$A$19,,-1) -> medium
A10: ='Formatted Overall mix GI'!$A$21 -> District of Columbia | B10: ='Formatted Overall mix GI'!$B$21 -> 40.75 | C10: =_xlfn.XLOOKUP(A10,'Area Abbreviations'!B:B,'Area Abbreviations'!A:A) -> DC | D10: =_xlfn.XLOOKUP(B10,'Score System'!$D$15:$D$19,'Score System'!$A$15:$A$19,,-1) -> high
B11: =B10 -> 40.75 | C11: D.C. | D11: =D10 -> high
A12: ='Formatted Overall mix GI'!$A$23 -> Florida | B12: ='Formatted Overall mix GI'!$B$23 -> -3 | C12: =_xlfn.XLOOKUP(A12,'Area Abbreviations'!B:B,'Area Abbreviations'!A:A) -> FL | D12: =_xlfn.XLOOKUP(B12,'Score System'!$D$15:$D$19,'Score System'!$A$15:$A$19,,-1) -> negative
A13: ='Formatted Overall mix GI'!$A$25 -> Georgia | B13: ='Formatted Overall mix GI'!$B$25 -> -0.75 | C13: =_xlfn.XLOOKUP(A13,'Area Abbreviations'!B:B,'Area Abbreviations'!A:A) -> GA | D13: =_xlfn.XLOOKUP(B13,'Score System'!$D$15:$D$19,'Score System'!$A$15:$A$19,,-1) -> negative
A14: ='Formatted Overall mix GI'!$A$27 -> Guam | B14: ='Formatted Overall mix GI'!$B$27 -> 4.75 | C14: =_xlfn.XLOOKUP(A14,'Area Abbreviations'!B:B,'Area Abbreviations'!A:A) -> GU | D14: =_xlfn.XLOOKUP(B14,'Score System'!$D$15:$D$19,'Score System'!$A$15:$A$19,,-1) -> low
A15: ='Formatted Overall mix GI'!$A$29 -> Hawaii | B15: ='Formatted Overall mix GI'!$B$29 -> 33.25 | C15: =_xlfn.XLOOKUP(A15,'Area Abbreviations'!B:B,'Area Abbreviations'!A:A) -> HI | D15: =_xlfn.XLOOKUP(B15,'Score System'!$D$15:$D$19,'Score System'!$A$15:$A$19,,-1) -> medium
A16: ='Formatted Overall mix GI'!$A$31 -> Idaho | B16: ='Formatted Overall mix GI'!$B$31 -> -11.5 | C16: =_xlfn.XLOOKUP(A16,'Area Abbreviations'!B:B,'Area Abbreviations'!A:A) -> ID | D16: =_xlfn.XLOOKUP(B16,'Score System'!$D$15:$D$19,'Score System'!$A$15:$A$19,,-1) -> negative
A17: ='Formatted Overall mix GI'!$A$33 -> Illinois | B17: ='Formatted Overall mix GI'!$B$33 -> 45 | C17: =_xlfn.XLOOKUP(A17,'Area Abbreviations'!B:B,'Area Abbreviations'!A:A) -> IL | D17: =_xlfn.XLOOKUP(B17,'Score System'!$D$15:$D$19,'Score System'!$A$15:$A$19,,-1) -> high
A18: ='Formatted Overall mix GI'!$A$35 -> Indiana | B18: ='Formatted Overall mix GI'!$B$35 -> -2.75 | C18: =_xlfn.XLOOKUP(A18,'Area Abbreviations'!B:B,'Area Abbreviations'!A:A) -> IN | D18: =_xlfn.XLOOKUP(B18,'Score System'!$D$15:$D$19,'Score System'!$A$15:$A$19,,-1) -> negative
A19: ='Formatted Overall mix GI'!$A$37 -> Iowa | B19: ='Formatted Overall mix GI'!$B$37 -> 4.5 | C19: =_xlfn.XLOOKUP(A19,'Area Abbreviations'!B:B,'Area Abbreviations'!A:A) -> IA | D19: =_xlfn.XLOOKUP(B19,'Score System'!$D$15:$D$19,'Score System'!$A$15:$A$19,,-1) -> low
A20: ='Formatted Overall mix GI'!$A$39 -> Kansas | B20: ='Formatted Overall mix GI'!$B$39 -> 2.5 | C20: =_xlfn.XLOOKUP(A20,'Area Abbreviations'!B:B,'Area Abbreviations'!A:A) -> KS | D20: =_xlfn.XLOOKUP(B20,'Score System'!$D$15:$D$19,'Score System'!$A$15:$A$19,,-1) -> low
A21: ='Formatted Overall mix GI'!$A$41 -> Kentucky | B21: ='Formatted Overall mix GI'!$B$41 -> 4.75 | C21: =_xlfn.XLOOKUP(A21,'Area Abbreviations'!B:B,'Area Abbreviations'!A:A) -> KY | D21: =_xlfn.XLOOKUP(B21,'Score System'!$D$15:$D$19,'Score System'!$A$15:$A$19,,-1) -> low
A22: ='Formatted Overall mix GI'!$A$43 -> Louisiana | B22: ='Formatted Overall mix GI'!$B$43 -> -6.75 | C22: =_xlfn.XLOOKUP(A22,'Area Abbreviations'!B:B,'Area Abbreviations'!A:A) -> LA | D22: =_xlfn.XLOOKUP(B22,'Score System'!$D$15:$D$19,'Score System'!$A$15:$A$19,,-1) -> negative
A23: ='Formatted Overall mix GI'!$A$45 -> Maine | B23: ='Formatted Overall mix GI'!$B$45 -> 44.5 | C23: =_xlfn.XLOOKUP(A23,'Area Abbreviations'!B:B,'Area Abbreviations'!A:A) -> ME | D23: =_xlfn.XLOOKUP(B23,'Score System'!$D$15:$D$19,'Score System'!$A$15:$A$19,,-1) -> high
A24: ='Formatted Overall mix GI'!$A$47 -> Maryland | B24: ='Formatted Overall mix GI'!$B$47 -> 43 | C24: =_xlfn.XLOOKUP(A24,'Area Abbreviations'!B:B,'Area Abbreviations'!A:A) -> MD | D24: =_xlfn.XLOOKUP(B24,'Score System'!$D$15:$D$19,'Score System'!$A$15:$A$19,,-1) -> high
A25: ='Formatted Overall mix GI'!$A$49 -> Massachusetts | B25: ='Formatted Overall mix GI'!$B$49 -> 40 | C25: =_xlfn.XLOOKUP(A25,'Area Abbreviations'!B:B,'Area Abbreviations'!A:A) -> MA | D25: =_xlfn.XLOOKUP(B25,'Score System'!$D$15:$D$19,'Score System'!$A$15:$A$19,,-1) -> high
A26: ='Formatted Overall mix GI'!$A$51 -> Michigan | B26: ='Formatted Overall mix GI'!$B$51 -> 30 | C26: =_xlfn.XLOOKUP(A26,'Area Abbreviations'!B:B,'Area Abbreviations'!A:A) -> MI | D26: =_xlfn.XLOOKUP(B26,'Score System'!$D$15:$D$19,'Score System'!$A$15:$A$19,,-1) -> medium
A27: ='Formatted Overall mix GI'!$A$53 -> Minnesota | B27: ='Formatted Overall mix GI'!$B$53 -> 36.75 | C27: =_xlfn.XLOOKUP(A27,'Area Abbreviations'!B:B,'Area Abbreviations'!A:A) -> MN | D27: =_xlfn.XLOOKUP(B27,'Score System'!$D$15:$D$19,'Score System'!$A$15:$A$19,,-1) -> medium
A28: ='Formatted Overall mix GI'!$A$55 -> Mississippi | B28: ='Formatted Overall mix GI'!$B$55 -> -7.5 | C28: =_xlfn.XLOOKUP(A28,'Area Abbreviations'!B:B,'Area Abbreviations'!A:A) -> MS | D28: =_xlfn.XLOOKUP(B28,'Score System'!$D$15:$D$19,'Score System'!$A$15:$A$19,,-1) -> negative
A29: ='Formatted Overall mix GI'!$A$57 -> Missouri | B29: ='Formatted Overall mix GI'!$B$57 -> -1.5 | C29: =_xlfn.XLOOKUP(A29,'Area Abbreviations'!B:B,'Area Abbreviations'!A:A) -> MO | D29: =_xlfn.XLOOKUP(B29,'Score System'!$D$15:$D$19,'Score System'!$A$15:$A$19,,-1) -> negative
A30: ='Formatted Overall mix GI'!$A$59 -> Montana | B30: ='Formatted Overall mix GI'!$B$59 -> -3.75 | C30: =_xlfn.XLOOKUP(A30,'Area Abbreviations'!B:B,'Area Abbreviations'!A:A) -> MT | D30: =_xlfn.XLOOKUP(B30,'Score System'!$D$15:$D$19,'Score System'!$A$15:$A$19,,-1) -> negative
A31: ='Formatted Overall mix GI'!$A$61 -> Nebraska | B31: ='Formatted Overall mix GI'!$B$61 -> 1.25 | C31: =_xlfn.XLOOKUP(A31,'Area Abbreviations'!B:B,'Area Abbreviations'!A:A) -> NE | D31: =_xlfn.XLOOKUP(B31,'Score System'!$D$15:$D$19,'Score System'!$A$15:$A$19,,-1) -> low
A32: ='Formatted Overall mix GI'!$A$63 -> Nevada | B32: ='Formatted Overall mix GI'!$B$63 -> 42.25 | C32: =_xlfn.XLOOKUP(A32,'Area Abbreviations'!B:B,'Area Abbreviations'!A:A) -> NV | D32: =_xlfn.XLOOKUP(B32,'Score System'!$D$15:$D$19,'Score System'!$A$15:$A$19,,-1) -> high
A33: ='Formatted Overall mix GI'!$A$65 -> New Hampshire | B33: ='Formatted Overall mix GI'!$B$65 -> 32 | C33: =_xlfn.XLOOKUP(A33,'Area Abbreviations'!B:B,'Area Abbreviations'!A:A) -> NH | D33: =_xlfn.XLOOKUP(B33,'Score System'!$D$15:$D$19,'Score System'!$A$15:$A$19,,-1) -> medium
A34: ='Formatted Overall mix GI'!$A$67 -> New Jersey | B34: ='Formatted Overall mix GI'!$B$67 -> 41.75 | C34: =_xlfn.XLOOKUP(A34,'Area Abbreviations'!B:B,'Area Abbreviations'!A:A) -> NJ | D34: =_xlfn.XLOOKUP(B34,'Score System'!$D$15:$D$19,'Score System'!$A$15:$A$19,,-1) -> high
A35: ='Formatted Overall mix GI'!$A$69 -> New Mexico | B35: ='Formatted Overall mix GI'!$B$69 -> 36 | C35: =_xlfn.XLOOKUP(A35,'Area Abbreviations'!B:B,'Area Abbreviations'!A:A) -> NM | D35: =_xlfn.XLOOKUP(B35,'Score System'!$D$15:$D$19,'Score System'!$A$15:$A$19,,-1) -> medium
A36: ='Formatted Overall mix GI'!$A$71 -> New York | B36: ='Formatted Overall mix GI'!$B$71 -> 44.5 | C36: =_xlfn.XLOOKUP(A36,'Area Abbreviations'!B:B,'Area Abbreviations'!A:A) -> NY | D36: =_xlfn.XLOOKUP(B36,'Score System'!$D$15:$D$19,'Score System'!$A$15:$A$19,,-1) -> high
A37: ='Formatted Overall mix GI'!$A$73 -> North Carolina | B37: ='Formatted Overall mix GI'!$B$73 -> 6.25 | C37: =_xlfn.XLOOKUP(A37,'Area Abbreviations'!B:B,'Area Abbreviations'!A:A) -> NC | D37: =_xlfn.XLOOKUP(B37,'Score System'!$D$15:$D$19,'Score System'!$A$15:$A$19,,-1) -> low
A38: ='Formatted Overall mix GI'!$A$75 -> North Dakota | B38: ='Formatted Overall mix GI'!$B$75 -> 10.5 | C38: =_xlfn.XLOOKUP(A38,'Area Abbreviations'!B:B,'Area Abbreviations'!A:A) -> ND | D38: =_xlfn.XLOOKUP(B38,'Score System'!$D$15:$D$19,'Score System'!$A$15:$A$19,,-1) -> low
A39: ='Formatted Overall mix GI'!$A$77 -> Northern Mariana Islands | B39: ='Formatted Overall mix GI'!$B$77 -> 2.75 | C39: =_xlfn.XLOOKUP(A39,'Area Abbreviations'!B:B,'Area Abbreviations'!A:A) -> MP | D39: =_xlfn.XLOOKUP(B39,'Score System'!$D$15:$D$19,'Score System'!$A$15:$A$19,,-1) -> low
A40: ='Formatted Overall mix GI'!$A$79 -> Ohio | B40: ='Formatted Overall mix GI'!$B$79 -> 1.75 | C40: =_xlfn.XLOOKUP(A40,'Area Abbreviations'!B:B,'Area Abbreviations'!A:A) -> OH | D40: =_xlfn.XLOOKUP(B40,'Score System'!$D$15:$D$19,'Score System'!$A$15:$A$19,,-1) -> low
...
